2018-01-10 22:41:55,099 ERROR: Exception on /login [POST] [in /Users/flaviovisetti/.local/share/virtualenvs/microblog--M0ad26m/lib/python3.6/site-packages/flask/app.py:1560]
Traceback (most recent call last):
  File "/Users/flaviovisetti/.local/share/virtualenvs/microblog--M0ad26m/lib/python3.6/site-packages/flask/app.py", line 1982, in wsgi_app
    response = self.full_dispatch_request()
  File "/Users/flaviovisetti/.local/share/virtualenvs/microblog--M0ad26m/lib/python3.6/site-packages/flask/app.py", line 1614, in full_dispatch_request
    rv = self.handle_user_exception(e)
  File "/Users/flaviovisetti/.local/share/virtualenvs/microblog--M0ad26m/lib/python3.6/site-packages/flask/app.py", line 1517, in handle_user_exception
    reraise(exc_type, exc_value, tb)
  File "/Users/flaviovisetti/.local/share/virtualenvs/microblog--M0ad26m/lib/python3.6/site-packages/flask/_compat.py", line 33, in reraise
    raise value
  File "/Users/flaviovisetti/.local/share/virtualenvs/microblog--M0ad26m/lib/python3.6/site-packages/flask/app.py", line 1612, in full_dispatch_request
    rv = self.dispatch_request()
  File "/Users/flaviovisetti/.local/share/virtualenvs/microblog--M0ad26m/lib/python3.6/site-packages/flask/app.py", line 1598, in dispatch_request
    return self.view_functions[rule.endpoint](**req.view_args)
  File "/Users/flaviovisetti/workspace/personal/python-projects/microblog/app/routes.py", line 41, in login
    if user is None or not user.check_password(form.password.data):
  File "/Users/flaviovisetti/workspace/personal/python-projects/microblog/app/models.py", line 25, in check_password
    return check_password_hash(self.password_hash, password)
  File "/Users/flaviovisetti/.local/share/virtualenvs/microblog--M0ad26m/lib/python3.6/site-packages/werkzeug/security.py", line 245, in check_password_hash
    if pwhash.count('$') < 2:
AttributeError: 'NoneType' object has no attribute 'count'
2018-01-11 01:34:00,492 ERROR: Exception on /susan [GET] [in /Users/flaviovisetti/.local/share/virtualenvs/microblog--M0ad26m/lib/python3.6/site-packages/flask/app.py:1560]
Traceback (most recent call last):
  File "/Users/flaviovisetti/.local/share/virtualenvs/microblog--M0ad26m/lib/python3.6/site-packages/flask/app.py", line 1612, in full_dispatch_request
    rv = self.dispatch_request()
  File "/Users/flaviovisetti/.local/share/virtualenvs/microblog--M0ad26m/lib/python3.6/site-packages/flask/app.py", line 1590, in dispatch_request
    self.raise_routing_exception(req)
  File "/Users/flaviovisetti/.local/share/virtualenvs/microblog--M0ad26m/lib/python3.6/site-packages/flask/app.py", line 1573, in raise_routing_exception
    raise request.routing_exception
  File "/Users/flaviovisetti/.local/share/virtualenvs/microblog--M0ad26m/lib/python3.6/site-packages/flask/ctx.py", line 294, in match_request
    self.url_adapter.match(return_rule=True)
  File "/Users/flaviovisetti/.local/share/virtualenvs/microblog--M0ad26m/lib/python3.6/site-packages/werkzeug/routing.py", line 1581, in match
    raise NotFound()
werkzeug.exceptions.NotFound: 404 Not Found: The requested URL was not found on the server.  If you entered the URL manually please check your spelling and try again.

During handling of the above exception, another exception occurred:

Traceback (most recent call last):
  File "/Users/flaviovisetti/.local/share/virtualenvs/microblog--M0ad26m/lib/python3.6/site-packages/flask/app.py", line 1982, in wsgi_app
    response = self.full_dispatch_request()
  File "/Users/flaviovisetti/.local/share/virtualenvs/microblog--M0ad26m/lib/python3.6/site-packages/flask/app.py", line 1614, in full_dispatch_request
    rv = self.handle_user_exception(e)
  File "/Users/flaviovisetti/.local/share/virtualenvs/microblog--M0ad26m/lib/python3.6/site-packages/flask/app.py", line 1512, in handle_user_exception
    return self.handle_http_exception(e)
  File "/Users/flaviovisetti/.local/share/virtualenvs/microblog--M0ad26m/lib/python3.6/site-packages/flask/app.py", line 1471, in handle_http_exception
    return handler(e)
  File "/Users/flaviovisetti/workspace/personal/python-projects/microblog/app/errors.py", line 6, in not_found_error
    return render_template('400.html'), 404
  File "/Users/flaviovisetti/.local/share/virtualenvs/microblog--M0ad26m/lib/python3.6/site-packages/flask/templating.py", line 133, in render_template
    return _render(ctx.app.jinja_env.get_or_select_template(template_name_or_list),
  File "/Users/flaviovisetti/.local/share/virtualenvs/microblog--M0ad26m/lib/python3.6/site-packages/jinja2/environment.py", line 869, in get_or_select_template
    return self.get_template(template_name_or_list, parent, globals)
  File "/Users/flaviovisetti/.local/share/virtualenvs/microblog--M0ad26m/lib/python3.6/site-packages/jinja2/environment.py", line 830, in get_template
    return self._load_template(name, self.make_globals(globals))
  File "/Users/flaviovisetti/.local/share/virtualenvs/microblog--M0ad26m/lib/python3.6/site-packages/jinja2/environment.py", line 804, in _load_template
    template = self.loader.load(self, name, globals)
  File "/Users/flaviovisetti/.local/share/virtualenvs/microblog--M0ad26m/lib/python3.6/site-packages/jinja2/loaders.py", line 113, in load
    source, filename, uptodate = self.get_source(environment, name)
  File "/Users/flaviovisetti/.local/share/virtualenvs/microblog--M0ad26m/lib/python3.6/site-packages/flask/templating.py", line 57, in get_source
    return self._get_source_fast(environment, template)
  File "/Users/flaviovisetti/.local/share/virtualenvs/microblog--M0ad26m/lib/python3.6/site-packages/flask/templating.py", line 85, in _get_source_fast
    raise TemplateNotFound(template)
jinja2.exceptions.TemplateNotFound: 400.html
